<?xml version="1.0" ?>
<robot name="joint_module" xmlns:xacro="http://ros.org/wiki/xacro">
  <material name="blue">
    <color rgba="0 0 0.8 1"/>
  </material>
  <material name="black">
    <color rgba="0 0 0 1"/>
  </material>
  <material name="white">
    <color rgba="1 1 1 1"/>
  </material>
  <link name="base_link">
    <visual>
      <origin rpy = "0 0 0" xyz = "0 0 0"/>
    </visual>
  </link>
  <joint name="fixed" type="fixed">
    <parent link="base_link"/>
    <child link="link_0"/>
    <axis rpy="0 0 0" xyz="0 0 1"/>
    <origin rpy="0.0 0.0 0.0" xyz="0.0 0.0 0.0"/>
  </joint>
  <link name ="link_0">
    <visual>
    <origin rpy="0 0 0" xyz="0 0 0.1"/>
    <geometry>
      <cylinder length="0.2" radius="0.1"/>
    </geometry>
    <material name="blue"/>
    </visual>
    <collision>
    <origin rpy="0 0 0" xyz="0 0 0"/>
    <geometry>
      <cylinder length="0.2" radius="0.1"/>
    </geometry>
    </collision>
    <inertial>
    <mass value="1"/>
    <inertia ixx="1.0" ixy="0.0" ixz="0.0" iyy="1.0" iyz="0.0" izz="1.0"/>
    </inertial>
  </link>
  <joint type="revolute">
    <axis rpy="0 0 0" xyz="0 0 1"/>
    <origin rpy="0.0 0.0 0.0" xyz="0.0 0.0 0.2"/>
    <parent link="link_0"/>
    <child link="link_1"/> 
    <limit lower="-3.14" upper="3.14" effort="35" velocity="5.7"/>
  </joint>
  <link name="link_1"/>
</robot>