<?xml version="1.0" ?>
<!-- =================================================================================== -->
<!-- |    This document was autogenerated by xacro from /home/edoardo/MultiDoF-superbuild/external/modular/ModularBot/urdf/ModularBot.urdf.xacro | -->
<!-- |    EDITING THIS FILE BY HAND IS NOT RECOMMENDED                                 | -->
<!-- =================================================================================== -->
<robot name="ModularBot" xmlns:xacro="http://ros.org/wiki/xacro">
  <gazebo>
    <plugin filename="libGazeboXBotPlugin.so" name="gazebo_xbot_plugin">
      <path_to_config_file>configs/ADVR_shared/ModularBot/configs/config_ModularBot.yaml</path_to_config_file>
    </plugin>
  </gazebo>
  <material name="blue">
    <color rgba="0 0 0.8 1"/>
  </material>
  <material name="black">
    <color rgba="0 0 0 1"/>
  </material>
  <material name="white">
    <color rgba="1 1 1 1"/>
  </material>
  <material name="grey">
    <color rgba="0.5 0.5 0.5 1"/>
  </material>
  <material name="red">
    <color rgba="1 0 0 1"/>
  </material>
  <material name="green">
    <color rgba="0 1 0 1"/>
  </material>
  <material name="yellow">
    <color rgba="1 1 0 1"/>
  </material>
  <material name="tree_green">
    <color rgba="0.13 0.54 0.13 1"/>
  </material>
  <link name="base_link"/>
  <joint name="fixed_table" type="fixed">
    <axis rpy="0 0 0" xyz="0 0 1"/>
    <parent link="base_link"/>
    <child link="table"/>
    <origin rpy="0.0 -0.0 0.0" xyz="0.0 0.0 0.0"/>
  </joint>
  <link name="table">
    <visual>
      <origin rpy="0 0 0" xyz="0.3 0 -0.005"/>
      <geometry>
        <box size="0.6 0.6 0.01"/>
      </geometry>
      <material name="gray"/>
    </visual>
    <collision>
      <origin rpy="0 0 0" xyz="0.25 0 -0.005"/>
      <geometry>
        <box size="0.6 0.6 0.01"/>
      </geometry>
    </collision>
    <inertial>
      <origin rpy="0 0 0" xyz="0 0 0.00"/>
      <mass value="0.5"/>
      <inertia ixx="0.0006" ixy="0.0" ixz="0.0" iyy="0.0006" iyz="0.0" izz="0.0006"/>
    </inertial>
  </link>
  <link name="L_0_A">
    <visual>
      <origin rpy="0 0 0" xyz="0 0 0.0"/>
      <geometry>
        <cylinder length="0.0" radius="0.06"/>
      </geometry>
      <material name="white"/>
    </visual>
    <collision>
      <origin rpy="0 0 0" xyz="0 0 0.0"/>
      <geometry>
        <cylinder length="0.0" radius="0.06"/>
      </geometry>
    </collision>
    <inertial>
      <origin rpy="0 0 0" xyz="0 0 0.0"/>
      <mass value="0.5"/>
      <inertia ixx="0.00045" ixy="0.0" ixz="0.0" iyy="0.00045" iyz="0.0" izz="0.0009"/>
    </inertial>
  </link>
  <gazebo reference="L_0_A">
    <mu1>0.2</mu1>
    <mu2>0.2</mu2>
    <kp>1000000.0</kp>
    <kd>1.0</kd>
    <maxVel>0.0</maxVel>
    <minDepth>0.0001</minDepth>
    <material>Gazebo/White</material>
  </gazebo>
  <joint name="L_0_A_fixed_joint_0" type="fixed">
    <axis rpy="0 0 0" xyz="0 0 1"/>
    <parent link="table"/>
    <child link="L_0_A"/>
    <origin rpy="0.0 -0.0 0.0" xyz="0.0 0.0 0.0"/>
  </joint>
  <joint name="fixed_J1_A" type="fixed">
    <axis rpy="0 0 0" xyz="0 0 1"/>
    <parent link="L_0_A"/>
    <child link="J1_A_stator"/>
    <origin rpy="0.0 -0.0 0.0" xyz="0.0 0.0 0.0"/>
  </joint>
  <link name="J1_A_stator">
    <visual>
      <origin rpy="0.0 0.0 0.0" xyz="0.0 0.0 0.0"/>
      <geometry>
        <mesh filename="package://modular/meshes/elbow_base.stl" scale="0.001 0.001 0.001"/>
      </geometry>
      <material name="tree_green"/>
    </visual>
    <collision>
      <origin rpy="0.0 0.0 0.0" xyz="0.0 0.0 0.0"/>
      <geometry>
        <mesh filename="package://modular/meshes/simple/elbow_base.stl" scale="0.001 0.001 0.001"/>
      </geometry>
    </collision>
    <inertial>
      <origin rpy="0 0 0" xyz="0.0 -0.013666345 0.095904755"/>
      <mass value="1.8627994"/>
      <inertia ixx="0.0080669105" ixy="6.8780537e-06" ixz="2.4976943e-05" iyy="0.0069731259" iyz="0.00033158425" izz="0.0037855995"/>
    </inertial>
  </link>
  <gazebo reference="J1_A_stator">
    <mu1>0.2</mu1>
    <mu2>0.2</mu2>
    <kp>1000000.0</kp>
    <kd>1.0</kd>
    <maxVel>0.0</maxVel>
    <minDepth>0.0001</minDepth>
    <material>Gazebo/Blue</material>
  </gazebo>
  <joint name="J1_A" type="revolute">
    <axis rpy="0 0 0" xyz="0 0 1"/>
    <parent link="J1_A_stator"/>
    <child link="L_1_A"/>
    <origin rpy="-1.57 -0.0 0.0" xyz="0.0 0.0721499771235 0.132057454972"/>
    <limit effort="147" lower="-2.0" upper="2.0" velocity="3.9"/>
  </joint>
  <link name="L_1_A">
    <visual>
      <origin rpy="0.0 3.14 0.0" xyz="0.0 0.0 -0.072"/>
      <geometry>
        <mesh filename="package://modular/meshes/elbow_link.stl" scale="0.001 0.001 0.001"/>
      </geometry>
      <material name="tree_green"/>
    </visual>
    <collision>
      <origin rpy="0.0 3.14 0.0" xyz="0.0 0.0 -0.072"/>
      <geometry>
        <mesh filename="package://modular/meshes/simple/elbow_link.stl" scale="0.001 0.001 0.001"/>
      </geometry>
    </collision>
    <inertial>
      <origin rpy="0 0 0" xyz="0.0 -0.040608854 -0.038467625"/>
      <mass value="1.1036463"/>
      <inertia ixx="0.0048243291" ixy="6.7819559e-06" ixz="-3.6661875e-06" iyy="0.0024139151" iyz="-0.0010484708" izz="0.0049751925"/>
    </inertial>
  </link>
  <joint name="fixed_L_1_A_rotor_fast" type="fixed">
    <axis rpy="0 0 0" xyz="0 0 1"/>
    <parent link="L_1_A"/>
    <child link="L_1_A_rotor_fast"/>
    <origin rpy="0.0 -0.0 0.0" xyz="0.0 0.0 0.0"/>
  </joint>
  <link name="L_1_A_rotor_fast">
    <inertial>
      <origin rpy="0 0 0" xyz="0.0 0.0 -0.0978986"/>
      <mass value="0.197124"/>
      <inertia ixx="0.00016128216" ixy="-2.4229e-07" ixz="3.771218e-06" iyy="0.00016138868" iyz="-2.4900687e-06" izz="1.287638e-05"/>
    </inertial>
  </link>
  <joint name="fixed_J2_A" type="fixed">
    <axis rpy="0 0 0" xyz="0 0 1"/>
    <parent link="L_1_A"/>
    <child link="J2_A_stator"/>
    <origin rpy="1.57 -0.0 0.0" xyz="0.0 -0.131999958147 -0.0720448848742"/>
  </joint>
  <link name="J2_A_stator">
    <visual>
      <origin rpy="0.0 0.0 0.0" xyz="0.0 0.0 0.0"/>
      <geometry>
        <mesh filename="package://modular/meshes/elbow_base.stl" scale="0.001 0.001 0.001"/>
      </geometry>
      <material name="tree_green"/>
    </visual>
    <collision>
      <origin rpy="0.0 0.0 0.0" xyz="0.0 0.0 0.0"/>
      <geometry>
        <mesh filename="package://modular/meshes/simple/elbow_base.stl" scale="0.001 0.001 0.001"/>
      </geometry>
    </collision>
    <inertial>
      <origin rpy="0 0 0" xyz="0.0 -0.013666345 0.095904755"/>
      <mass value="1.8627994"/>
      <inertia ixx="0.0080669105" ixy="6.8780537e-06" ixz="2.4976943e-05" iyy="0.0069731259" iyz="0.00033158425" izz="0.0037855995"/>
    </inertial>
  </link>
  <gazebo reference="J2_A_stator">
    <mu1>0.2</mu1>
    <mu2>0.2</mu2>
    <kp>1000000.0</kp>
    <kd>1.0</kd>
    <maxVel>0.0</maxVel>
    <minDepth>0.0001</minDepth>
    <material>Gazebo/Blue</material>
  </gazebo>
  <joint name="J2_A" type="revolute">
    <axis rpy="0 0 0" xyz="0 0 1"/>
    <parent link="J2_A_stator"/>
    <child link="L_2_A"/>
    <origin rpy="-1.57 -0.0 0.0" xyz="0.0 0.0721499771235 0.132057454972"/>
    <limit effort="147" lower="-2.0" upper="2.0" velocity="3.9"/>
  </joint>
  <link name="L_2_A">
    <visual>
      <origin rpy="0.0 3.14 0.0" xyz="0.0 0.0 -0.072"/>
      <geometry>
        <mesh filename="package://modular/meshes/elbow_link.stl" scale="0.001 0.001 0.001"/>
      </geometry>
      <material name="tree_green"/>
    </visual>
    <collision>
      <origin rpy="0.0 3.14 0.0" xyz="0.0 0.0 -0.072"/>
      <geometry>
        <mesh filename="package://modular/meshes/simple/elbow_link.stl" scale="0.001 0.001 0.001"/>
      </geometry>
    </collision>
    <inertial>
      <origin rpy="0 0 0" xyz="0.0 -0.040608854 -0.038467625"/>
      <mass value="1.1036463"/>
      <inertia ixx="0.0048243291" ixy="6.7819559e-06" ixz="-3.6661875e-06" iyy="0.0024139151" iyz="-0.0010484708" izz="0.0049751925"/>
    </inertial>
  </link>
  <joint name="fixed_L_2_A_rotor_fast" type="fixed">
    <axis rpy="0 0 0" xyz="0 0 1"/>
    <parent link="L_2_A"/>
    <child link="L_2_A_rotor_fast"/>
    <origin rpy="0 0 0" xyz="0 0 0"/>
  </joint>
  <link name="L_2_A_rotor_fast">
    <inertial>
      <origin rpy="0 0 0" xyz="0.0 0.0 -0.0978986"/>
      <mass value="0.197124"/>
      <inertia ixx="0.00016128216" ixy="-2.4229e-07" ixz="3.771218e-06" iyy="0.00016138868" iyz="-2.4900687e-06" izz="1.287638e-05"/>
    </inertial>
  </link>
  <joint name="fixed_J3_A" type="fixed">
    <axis rpy="0 0 0" xyz="0 0 1"/>
    <parent link="L_2_A"/>
    <child link="J3_A_stator"/>
    <origin rpy="1.57 -0.0 0.0" xyz="0.0 -0.131999958147 -0.0720448848742"/>
  </joint>
  <link name="J3_A_stator">
    <visual>
      <origin rpy="0.0 0.0 0.0" xyz="0.0 0.0 0.0"/>
      <geometry>
        <mesh filename="package://modular/meshes/yaw_base.stl" scale="0.001 0.001 0.001"/>
      </geometry>
      <material name="tree_green"/>
    </visual>
    <collision>
      <origin rpy="0.0 0.0 0.0" xyz="0.0 0.0 0.0"/>
      <geometry>
        <mesh filename="package://modular/meshes/simple/yaw_base.stl" scale="0.001 0.001 0.001"/>
      </geometry>
    </collision>
    <inertial>
      <origin rpy="0 0 0" xyz="0.0 0.0 0.10614489"/>
      <mass value="2.0554934"/>
      <inertia ixx="0.01068855" ixy="-1.14168e-05" ixz="2.71689e-06" iyy="0.010584907" iyz="8.76312e-05" izz="0.0032026258"/>
    </inertial>
  </link>
  <gazebo reference="J3_A_stator">
    <mu1>0.2</mu1>
    <mu2>0.2</mu2>
    <kp>1000000.0</kp>
    <kd>1.0</kd>
    <maxVel>0.0</maxVel>
    <minDepth>0.0001</minDepth>
    <material>Gazebo/Blue</material>
  </gazebo>
  <joint name="J3_A" type="revolute">
    <axis rpy="0 0 0" xyz="0 0 1"/>
    <parent link="J3_A_stator"/>
    <child link="L_3_A"/>
    <origin rpy="0.0 -0.0 0.0" xyz="0.0 0.0 0.214"/>
    <limit effort="147" lower="-2.8" upper="2.8" velocity="3.9"/>
  </joint>
  <link name="L_3_A">
    <visual>
      <origin rpy="0.0 0.0 0.0" xyz="0.0 0.0 0.0"/>
      <geometry>
        <mesh filename="package://modular/meshes/yaw_link.stl" scale="0.001 0.001 0.001"/>
      </geometry>
      <material name="tree_green"/>
    </visual>
    <collision>
      <origin rpy="0.0 0.0 0.0" xyz="0.0 0.0 0.0"/>
      <geometry>
        <mesh filename="package://modular/meshes/simple/yaw_link.stl" scale="0.001 0.001 0.001"/>
      </geometry>
    </collision>
    <inertial>
      <origin rpy="0 0 0" xyz="0.0 0.0 -0.024438213"/>
      <mass value="0.42322395"/>
      <inertia ixx="0.00063746146" ixy="1.1903424e-05" ixz="6.7230372e-07" iyy="0.00064218987" iyz="2.203073e-05" izz="0.001009674"/>
    </inertial>
  </link>
  <joint name="fixed_L_3_A_rotor_fast" type="fixed">
    <axis rpy="0 0 0" xyz="0 0 1"/>
    <parent link="L_3_A"/>
    <child link="L_3_A_rotor_fast"/>
    <origin rpy="0 0 0" xyz="0 0 0"/>
  </joint>
  <link name="L_3_A_rotor_fast">
    <inertial>
      <origin rpy="0 0 0" xyz="0.0 0.0 -0.0978986"/>
      <mass value="0.197124"/>
      <inertia ixx="0.00016128216" ixy="-2.4229e-07" ixz="3.771218e-06" iyy="0.00016138868" iyz="-2.4900687e-06" izz="1.287638e-05"/>
    </inertial>
  </link>
  <joint name="fixed_J4_A" type="fixed">
    <axis rpy="0 0 0" xyz="0 0 1"/>
    <parent link="L_3_A"/>
    <child link="J4_A_stator"/>
    <origin rpy="0.0 -0.0 0.0" xyz="0.0 0.0 0.0"/>
  </joint>
  <link name="J4_A_stator">
    <visual>
      <origin rpy="0.0 0.0 0.0" xyz="0.0 0.0 0.0"/>
      <geometry>
        <mesh filename="package://modular/meshes/elbow_base.stl" scale="0.001 0.001 0.001"/>
      </geometry>
      <material name="tree_green"/>
    </visual>
    <collision>
      <origin rpy="0.0 0.0 0.0" xyz="0.0 0.0 0.0"/>
      <geometry>
        <mesh filename="package://modular/meshes/simple/elbow_base.stl" scale="0.001 0.001 0.001"/>
      </geometry>
    </collision>
    <inertial>
      <origin rpy="0 0 0" xyz="0.0 -0.013666345 0.095904755"/>
      <mass value="1.8627994"/>
      <inertia ixx="0.0080669105" ixy="6.8780537e-06" ixz="2.4976943e-05" iyy="0.0069731259" iyz="0.00033158425" izz="0.0037855995"/>
    </inertial>
  </link>
  <gazebo reference="J4_A_stator">
    <mu1>0.2</mu1>
    <mu2>0.2</mu2>
    <kp>1000000.0</kp>
    <kd>1.0</kd>
    <maxVel>0.0</maxVel>
    <minDepth>0.0001</minDepth>
    <material>Gazebo/Blue</material>
  </gazebo>
  <joint name="J4_A" type="revolute">
    <axis rpy="0 0 0" xyz="0 0 1"/>
    <parent link="J4_A_stator"/>
    <child link="L_4_A"/>
    <origin rpy="-1.57 -0.0 0.0" xyz="0.0 0.0721499771235 0.132057454972"/>
    <limit effort="147" lower="-2.0" upper="2.0" velocity="3.9"/>
  </joint>
  <link name="L_4_A">
    <visual>
      <origin rpy="0.0 3.14 0.0" xyz="0.0 0.0 -0.072"/>
      <geometry>
        <mesh filename="package://modular/meshes/elbow_link.stl" scale="0.001 0.001 0.001"/>
      </geometry>
      <material name="tree_green"/>
    </visual>
    <collision>
      <origin rpy="0.0 3.14 0.0" xyz="0.0 0.0 -0.072"/>
      <geometry>
        <mesh filename="package://modular/meshes/simple/elbow_link.stl" scale="0.001 0.001 0.001"/>
      </geometry>
    </collision>
    <inertial>
      <origin rpy="0 0 0" xyz="0.0 -0.040608854 -0.038467625"/>
      <mass value="1.1036463"/>
      <inertia ixx="0.0048243291" ixy="6.7819559e-06" ixz="-3.6661875e-06" iyy="0.0024139151" iyz="-0.0010484708" izz="0.0049751925"/>
    </inertial>
  </link>
  <joint name="fixed_L_4_A_rotor_fast" type="fixed">
    <axis rpy="0 0 0" xyz="0 0 1"/>
    <parent link="L_4_A"/>
    <child link="L_4_A_rotor_fast"/>
    <origin rpy="0 0 0" xyz="0 0 0"/>
  </joint>
  <link name="L_4_A_rotor_fast">
    <inertial>
      <origin rpy="0 0 0" xyz="0.0 0.0 -0.0978986"/>
      <mass value="0.197124"/>
      <inertia ixx="0.00016128216" ixy="-2.4229e-07" ixz="3.771218e-06" iyy="0.00016138868" iyz="-2.4900687e-06" izz="1.287638e-05"/>
    </inertial>
  </link>
  <link name="ee_A">
    <inertial>
      <origin rpy="0 0 0" xyz="0 0 0.0945"/>
      <mass value="0.848"/>
      <inertia ixx="1.1564566e-03" ixy="0.0" ixz="0.0" iyy="1.2469918e-03" iyz="0.0" izz="5.7388903e-04"/>
    </inertial>
  </link>
  <joint name="L_4_fixed_joint_0_A" type="fixed">
    <axis rpy="0 0 0" xyz="0 0 1"/>
    <parent link="L_4_A"/>
    <child link="ee_A"/>
    <origin rpy="1.57 -0.0 0.0" xyz="0.0 -0.320999898221 -0.0718943791259"/>
  </joint>
  <link name="L_0_B">
    <visual>
      <origin rpy="0 0 0" xyz="0 0 0.0"/>
      <geometry>
        <cylinder length="0.0" radius="0.06"/>
      </geometry>
      <material name="white"/>
    </visual>
    <collision>
      <origin rpy="0 0 0" xyz="0 0 0.0"/>
      <geometry>
        <cylinder length="0.0" radius="0.06"/>
      </geometry>
    </collision>
    <inertial>
      <origin rpy="0 0 0" xyz="0 0 0.0"/>
      <mass value="0.5"/>
      <inertia ixx="0.00045" ixy="0.0" ixz="0.0" iyy="0.00045" iyz="0.0" izz="0.0009"/>
    </inertial>
  </link>
  <gazebo reference="L_0_B">
    <mu1>0.2</mu1>
    <mu2>0.2</mu2>
    <kp>1000000.0</kp>
    <kd>1.0</kd>
    <maxVel>0.0</maxVel>
    <minDepth>0.0001</minDepth>
    <material>Gazebo/White</material>
  </gazebo>
  <joint name="L_0_B_fixed_joint_0" type="fixed">
    <axis rpy="0 0 0" xyz="0 0 1"/>
    <parent link="table"/>
    <child link="L_0_B"/>
    <origin rpy="0.0 -0.0 3.14" xyz="0.6 0.0 0.0"/>
  </joint>
  <joint name="fixed_J1_B" type="fixed">
    <axis rpy="0 0 0" xyz="0 0 1"/>
    <parent link="L_0_B"/>
    <child link="J1_B_stator"/>
    <origin rpy="0.0 -0.0 0.0" xyz="0.0 0.0 0.0"/>
  </joint>
  <link name="J1_B_stator">
    <visual>
      <origin rpy="0.0 0.0 0.0" xyz="0.0 0.0 0.0"/>
      <geometry>
        <mesh filename="package://modular/meshes/yaw_base.stl" scale="0.001 0.001 0.001"/>
      </geometry>
      <material name="tree_green"/>
    </visual>
    <collision>
      <origin rpy="0.0 0.0 0.0" xyz="0.0 0.0 0.0"/>
      <geometry>
        <mesh filename="package://modular/meshes/simple/yaw_base.stl" scale="0.001 0.001 0.001"/>
      </geometry>
    </collision>
    <inertial>
      <origin rpy="0 0 0" xyz="0.0 0.0 0.10614489"/>
      <mass value="2.0554934"/>
      <inertia ixx="0.01068855" ixy="-1.14168e-05" ixz="2.71689e-06" iyy="0.010584907" iyz="8.76312e-05" izz="0.0032026258"/>
    </inertial>
  </link>
  <gazebo reference="J1_B_stator">
    <mu1>0.2</mu1>
    <mu2>0.2</mu2>
    <kp>1000000.0</kp>
    <kd>1.0</kd>
    <maxVel>0.0</maxVel>
    <minDepth>0.0001</minDepth>
    <material>Gazebo/Blue</material>
  </gazebo>
  <joint name="J1_B" type="revolute">
    <axis rpy="0 0 0" xyz="0 0 1"/>
    <parent link="J1_B_stator"/>
    <child link="L_1_B"/>
    <origin rpy="0.0 -0.0 0.0" xyz="0.0 0.0 0.214"/>
    <limit effort="147" lower="-2.8" upper="2.8" velocity="3.9"/>
  </joint>
  <link name="L_1_B">
    <visual>
      <origin rpy="0.0 0.0 0.0" xyz="0.0 0.0 0.0"/>
      <geometry>
        <mesh filename="package://modular/meshes/yaw_link.stl" scale="0.001 0.001 0.001"/>
      </geometry>
      <material name="tree_green"/>
    </visual>
    <collision>
      <origin rpy="0.0 0.0 0.0" xyz="0.0 0.0 0.0"/>
      <geometry>
        <mesh filename="package://modular/meshes/simple/yaw_link.stl" scale="0.001 0.001 0.001"/>
      </geometry>
    </collision>
    <inertial>
      <origin rpy="0 0 0" xyz="0.0 0.0 -0.024438213"/>
      <mass value="0.42322395"/>
      <inertia ixx="0.00063746146" ixy="1.1903424e-05" ixz="6.7230372e-07" iyy="0.00064218987" iyz="2.203073e-05" izz="0.001009674"/>
    </inertial>
  </link>
  <joint name="fixed_L_1_B_rotor_fast" type="fixed">
    <axis rpy="0 0 0" xyz="0 0 1"/>
    <parent link="L_1_B"/>
    <child link="L_1_B_rotor_fast"/>
    <origin rpy="0.0 -0.0 0.0" xyz="0.0 0.0 0.0"/>
  </joint>
  <link name="L_1_B_rotor_fast">
    <inertial>
      <origin rpy="0 0 0" xyz="0.0 0.0 -0.0978986"/>
      <mass value="0.197124"/>
      <inertia ixx="0.00016128216" ixy="-2.4229e-07" ixz="3.771218e-06" iyy="0.00016138868" iyz="-2.4900687e-06" izz="1.287638e-05"/>
    </inertial>
  </link>
  <link name="ee_B">
    <inertial>
      <origin rpy="0 0 0" xyz="0 0 0.0375"/>
      <mass value="0.848"/>
      <inertia ixx="1.1564566e-03" ixy="0.0" ixz="0.0" iyy="1.2469918e-03" iyz="0.0" izz="5.7388903e-04"/>
    </inertial>
  </link>
  <joint name="L_1_fixed_joint_0_B" type="fixed">
    <axis rpy="0 0 0" xyz="0 0 1"/>
    <parent link="L_1_B"/>
    <child link="ee_B"/>
    <origin rpy="0.0 -0.0 0.0" xyz="0.0 0.0 0.075"/>
  </joint>
</robot>
