<?xml version="1.0" ?>
<!-- =================================================================================== -->
<!-- |    This document was autogenerated by xacro from ModularBot_Generated.urdf.xacro | -->
<!-- |    EDITING THIS FILE BY HAND IS NOT RECOMMENDED                                 | -->
<!-- =================================================================================== -->
<robot name="ModularBot" xmlns:xacro="http://ros.org/wiki/xacro">
  <material name="blue">
    <color rgba="0 0 0.8 1"/>
  </material>
  <material name="black">
    <color rgba="0 0 0 1"/>
  </material>
  <material name="white">
    <color rgba="1 1 1 1"/>
  </material>
  <link name="base_link"/>
  <link name="link_0">
    <visual>
      <origin rpy="0 0 0" xyz="0 0 0.2"/>
      <geometry>
        <cylinder length="0.4" radius="0.1"/>
      </geometry>
      <material name="black"/>
    </visual>
    <collision>
      <geometry>
        <cylinder length="0.4" radius="0.1"/>
      </geometry>
    </collision>
    <inertial>
      <mass value="10"/>
      <inertia ixx="1.0" ixy="0.0" ixz="0.0" iyy="1.0" iyz="0.0" izz="1.0"/>
    </inertial>
  </link>
  <joint name="fixed" type="fixed">
    <parent link="base_link"/>
    <child link="link_0"/>
  </joint>
  <link name="link_1">
    <visual>
      <origin rpy="0 0 0" xyz="0.4 0 0"/>
      <geometry>
        <box size="0.8 0.1 0.1"/>
      </geometry>
      <material name="blue"/>
    </visual>
    <collision>
      <origin rpy="0 0 0" xyz="0.4 0 0"/>
      <geometry>
        <box size="0.8 0.1 0.1"/>
      </geometry>
    </collision>
    <inertial>
      <mass value="1"/>
      <inertia ixx="1.0" ixy="0.0" ixz="0.0" iyy="1.0" iyz="0.0" izz="1.0"/>
    </inertial>
  </link>
  <joint name="joint_0_1" type="continuous">
    <axis rpy="0 0 0" xyz="0 0 1"/>
    <parent link="link_0"/>
    <child link="link_1"/>
    <origin rpy="0 0 0" xyz="0 0 0.4"/>
  </joint>
  <link name="link_2">
    <visual>
      <origin rpy="0 0 0" xyz="0.4 0 0"/>
      <geometry>
        <box size="0.8 0.1 0.1"/>
      </geometry>
      <material name="white"/>
    </visual>
    <collision>
      <origin rpy="0 0 0" xyz="0.4 0 0"/>
      <geometry>
        <box size="0.8 0.1 0.1"/>
      </geometry>
    </collision>
    <inertial>
      <mass value="1"/>
      <inertia ixx="1.0" ixy="0.0" ixz="0.0" iyy="1.0" iyz="0.0" izz="1.0"/>
    </inertial>
  </link>
  <joint name="joint_1_2" type="continuous">
    <axis rpy="0 0 0" xyz="0 0 1"/>
    <parent link="link_1"/>
    <child link="link_2"/>
    <origin rpy="-1.57075 0 0" xyz="0.8 0 0"/>
  </joint>
  <link name="link_3">
    <visual>
      <origin rpy="0 0 0" xyz="0.4 0 0"/>
      <geometry>
        <box size="0.8 0.1 0.1"/>
      </geometry>
      <material name="blue"/>
    </visual>
    <collision>
      <origin rpy="0 0 0" xyz="0.4 0 0"/>
      <geometry>
        <box size="0.8 0.1 0.1"/>
      </geometry>
    </collision>
    <inertial>
      <mass value="1"/>
      <inertia ixx="1.0" ixy="0.0" ixz="0.0" iyy="1.0" iyz="0.0" izz="1.0"/>
    </inertial>
  </link>
  <joint name="joint_2_3" type="continuous">
    <axis rpy="0 0 0" xyz="0 0 1"/>
    <parent link="link_2"/>
    <child link="link_3"/>
    <origin rpy="1.57075 0 0" xyz="0.8 0 0"/>
  </joint>
</robot>

