<?xml version="1.0" ?>
<robot name="ModularBot" xmlns:xacro="http://ros.org/wiki/xacro">

  <xacro:include filename="$(find modular)/urdf/config.xacro"/>
  <xacro:if value="${GAZEBO}">
    <xacro:include filename="$(find modular)/urdf/modular.gazebo"/>
  </xacro:if>
  
   <material name="blue">
    <color rgba="0 0 0.8 1"/>
  </material>
  <material name="black">
    <color rgba="0 0 0 1"/>
  </material>
  <material name="white">
    <color rgba="1 1 1 1"/>
  </material>
  <material name="grey">
    <color rgba="0.5 0.5 0.5 1"/>
  </material>
  <link name="world"/>
  <joint name="fixed" type="fixed">
    <parent link="world"/>
    <child link="L_0a"/>
  </joint>
  <!-- <link name="base_link">
    <visual>
      <origin rpy="0 0 0" xyz="0 0 0.05"/>
      <geometry>
        <cylinder length="0.1" radius="0.06"/>
      </geometry>
      <material name="black"/>
    </visual>
    <collision>
      <geometry>
        <cylinder length="0.1" radius="0.06"/>
      </geometry>
    </collision>
    <inertial>
      <mass value="0.5"/>
      <inertia ixx="1.0" ixy="0.0" ixz="0.0" iyy="1.0" iyz="0.0" izz="1.0"/>
    </inertial>
  </link>
  <joint name="J0" type="revolute">
    <parent link="base_link"/>
    <child link="L_0a"/>
    <axis rpy="0 0 0" xyz="0 0 1"/>
    <origin rpy="0.0 0.0 0.0" xyz="0.0 0.0 0.1"/>
    <limit effort="35" lower="-0.001" upper="0.001" velocity="5.7"/>
  </joint> -->
  <link name="L_0a">
    <visual>
      <origin rpy="0 0 0" xyz="0 0 1"/>
      <geometry>
        <box size="0.4 0.4 2"/>
      </geometry>
      <material name="black"/>
    </visual>
    <collision>
      <origin rpy="0 0 0" xyz="0 0 1"/>
      <geometry>
        <box size="0.4 0.4 2"/>
      </geometry>
    </collision>
    <inertial>
      <mass value="50"/>
      <inertia ixx="1.0" ixy="0.0" ixz="0.0" iyy="1.0" iyz="0.0" izz="1.0"/>
    </inertial>
  </link>
  <link name="L_0a_con2">
    <visual>
      <origin rpy="0 0 0" xyz="0 0 0.05"/>
      <geometry>
        <cylinder length="0.1" radius="0.06"/>
      </geometry>
      <material name="black"/>
    </visual>
    <collision>
      <origin rpy="0 0 0" xyz="0 0 0.05"/>
      <geometry>
        <cylinder length="0.1" radius="0.06"/>
      </geometry>
    </collision>
    <inertial>
      <mass value="0.5"/>
      <inertia ixx="1.0" ixy="0.0" ixz="0.0" iyy="1.0" iyz="0.0" izz="1.0"/>
    </inertial>
  </link>  
  <link name="L_0a_con4">
    <visual>
      <origin rpy="0 0 0" xyz="0 0 0.05"/>
      <geometry>
        <cylinder length="0.1" radius="0.06"/>
      </geometry>
      <material name="black"/>
    </visual>
    <collision>
      <origin rpy="0 0 0" xyz="0 0 0.05"/>
      <geometry>
        <cylinder length="0.1" radius="0.06"/>
      </geometry>
    </collision>
    <inertial>
      <mass value="0.5"/>
      <inertia ixx="1.0" ixy="0.0" ixz="0.0" iyy="1.0" iyz="0.0" izz="1.0"/>
    </inertial>
  </link>
  <joint name="L_0a_fixed_2" type="fixed">
    <parent link="L_0a"/>
    <child link="L_0a_con2"/>
    <axis rpy="0 0 0" xyz="0 0 1"/>
    <origin rpy="1.57 3.14 0" xyz="0 -0.2 1.8"/>
  </joint> 
  <joint name="L_0a_fixed_4" type="fixed">
    <parent link="L_0a"/>
    <child link="L_0a_con4"/>
    <axis rpy="0 0 0" xyz="0 0 1"/>
    <origin rpy="-1.57 0 0" xyz="0 0.2 1.8"/>
  </joint>

  <gazebo reference="L_0a">
    <mu1>1000000</mu1>
    <mu2>1000000</mu2>
    <kp>1000000000.0</kp>
    <kd>1.0</kd>
    <maxVel>0.0</maxVel>
    <minDepth>0.0001</minDepth>
  </gazebo>
  
  <!-- <joint name="J1_A" type="revolute">
    <axis rpy="0 0 0" xyz="0 0 1"/>
    <parent link="L_0a_con4"/>
    <child link="L_1_elbow_1_A"/>
    <origin rpy="0.0 0.0 0.0" xyz="0.0 0.0 0.1"/>
    <limit effort="300" lower="-3.14" upper="3.14" velocity="5.7"/>
  </joint>
  <link name="L_1_elbow_1_A">
    <visual>
      <origin rpy="0 0 0" xyz="0 0 0.1"/>
      <geometry>
        <cylinder length="0.2" radius="0.06"/>
      </geometry>
      <material name="white"/>
    </visual>
    <visual>
      <origin rpy="1.57 0 0" xyz="0 0.1 0.2"/>
      <geometry>
        <cylinder length="0.2" radius="0.06"/>
      </geometry>
      <material name="white"/>
    </visual>
    <visual>
      <origin rpy="0 0 0" xyz="0 0 0.2"/>
      <geometry>
        <sphere radius="0.06"/>
      </geometry>
      <material name="white"/>
    </visual>
    <collision>
      <origin rpy="0 0 0" xyz="0 0 0.1"/>
      <geometry>
        <cylinder length="0.2" radius="0.06"/>
      </geometry>
    </collision>
    <inertial>
      <origin rpy="0 0 0" xyz="0 0 0.1"/>
      <mass value="0.5"/>
      <inertia ixx="0.0171166666667" ixy="0.0" ixz="0.0" iyy="0.0140083333333" iyz="0.0" izz="0.00400833333333"/>
    </inertial>
    <collision>
      <origin rpy="1.57 0 0" xyz="0 0.1 0.2"/>
      <geometry>
        <cylinder length="0.2" radius="0.06"/>
      </geometry>
    </collision>
    <collision>
      <origin rpy="0 0 0" xyz="0 0 0.2"/>
      <geometry>
        <sphere radius="0.06"/>
      </geometry>
    </collision>
  </link>
  <gazebo reference="L_1_elbow_1_A">
    <mu1>0.2</mu1>
    <mu2>0.2</mu2>
    <kp>1000000.0</kp>
    <kd>1.0</kd>
    <maxVel>0.0</maxVel>
    <minDepth>0.0001</minDepth>
    <material>Gazebo/White</material>
  </gazebo>
  <link name="L_1_link_2_A">
    <visual>
      <origin rpy="0 0 0" xyz="0 0 0.15"/>
      <geometry>
        <cylinder length="0.3" radius="0.06"/>
      </geometry>
      <material name="black"/>
    </visual>
    <collision>
      <origin rpy="0 0 0" xyz="0 0 0.15"/>
      <geometry>
        <cylinder length="0.3" radius="0.06"/>
      </geometry>
    </collision>
    <inertial>
      <origin rpy="0 0 0" xyz="0 0 0.15"/>
      <mass value="0.5"/>
      <inertia ixx="0.0042" ixy="0.0" ixz="0.0" iyy="0.0042" iyz="0.0" izz="0.0009"/>
    </inertial>
  </link>
  <gazebo reference="L_1_link_2_A">
    <mu1>0.2</mu1>
    <mu2>0.2</mu2>
    <kp>1000000.0</kp>
    <kd>1.0</kd>
    <maxVel>0.0</maxVel>
    <minDepth>0.0001</minDepth>
    <material>Gazebo/White</material>
  </gazebo>
  <joint name="L_1_fixed_joint_2_A" type="fixed">
    <axis rpy="0 0 0" xyz="0 0 1"/>
    <parent link="L_1_elbow_1_A"/>
    <child link="L_1_link_2_A"/>
    <origin rpy="-1.57 -0.0 0.0" xyz="0.0 0.199999936586 0.200159265342"/>
  </joint>
   -->
  <joint name="J1_B" type="revolute">
    <axis rpy="0 0 0" xyz="0 0 1"/>
    <parent link="L_0a_con2"/>
    <child link="L_1_elbow_1_B"/>
    <origin rpy="0.0 0.0 0.0" xyz="0.0 0.0 0.1"/>
    <limit effort="300" lower="-3.14" upper="3.14" velocity="5.7"/>
  </joint>
  <link name="L_1_elbow_1_B">
    <visual>
      <origin rpy="0 0 0" xyz="0 0 0.1"/>
      <geometry>
        <cylinder length="0.2" radius="0.06"/>
      </geometry>
      <material name="white"/>
    </visual>
    <visual>
      <origin rpy="1.57 0 0" xyz="0 0.1 0.2"/>
      <geometry>
        <cylinder length="0.2" radius="0.06"/>
      </geometry>
      <material name="white"/>
    </visual>
    <visual>
      <origin rpy="0 0 0" xyz="0 0 0.2"/>
      <geometry>
        <sphere radius="0.06"/>
      </geometry>
      <material name="white"/>
    </visual>
    <collision>
      <origin rpy="0 0 0" xyz="0 0 0.1"/>
      <geometry>
        <cylinder length="0.2" radius="0.06"/>
      </geometry>
    </collision>
    <inertial>
      <origin rpy="0 0 0" xyz="0 0 0.1"/>
      <mass value="0.5"/>
      <inertia ixx="0.0171166666667" ixy="0.0" ixz="0.0" iyy="0.0140083333333" iyz="0.0" izz="0.00400833333333"/>
    </inertial>
    <collision>
      <origin rpy="1.57 0 0" xyz="0 0.1 0.2"/>
      <geometry>
        <cylinder length="0.2" radius="0.06"/>
      </geometry>
    </collision>
    <collision>
      <origin rpy="0 0 0" xyz="0 0 0.2"/>
      <geometry>
        <sphere radius="0.06"/>
      </geometry>
    </collision>
  </link>
  <gazebo reference="L_1_elbow_1_B">
    <mu1>0.2</mu1>
    <mu2>0.2</mu2>
    <kp>1000000.0</kp>
    <kd>1.0</kd>
    <maxVel>0.0</maxVel>
    <minDepth>0.0001</minDepth>
  </gazebo>
  <link name="L_1_link_2_B">
    <visual>
      <origin rpy="0 0 0" xyz="0 0 0.15"/>
      <geometry>
        <cylinder length="0.3" radius="0.06"/>
      </geometry>
      <material name="black"/>
    </visual>
    <collision>
      <origin rpy="0 0 0" xyz="0 0 0.15"/>
      <geometry>
        <cylinder length="0.3" radius="0.06"/>
      </geometry>
    </collision>
    <inertial>
      <origin rpy="0 0 0" xyz="0 0 0.15"/>
      <mass value="0.5"/>
      <inertia ixx="0.0042" ixy="0.0" ixz="0.0" iyy="0.0042" iyz="0.0" izz="0.0009"/>
    </inertial>
  </link>
  <gazebo reference="L_1_link_2_B">
    <mu1>0.2</mu1>
    <mu2>0.2</mu2>
    <kp>1000000.0</kp>
    <kd>1.0</kd>
    <maxVel>0.0</maxVel>
    <minDepth>0.0001</minDepth>
  </gazebo>
  <joint name="L_1_fixed_joint_2_B" type="fixed">
    <axis rpy="0 0 0" xyz="0 0 1"/>
    <parent link="L_1_elbow_1_B"/>
    <child link="L_1_link_2_B"/>
    <origin rpy="-1.57 -0.0 0.0" xyz="0.0 0.199999936586 0.200159265342"/>
  </joint>

  <joint name="J2_B" type="revolute">
    <axis rpy="0 0 0" xyz="0 0 1"/>
    <parent link="L_1_link_2_B"/>
    <child link="L_2_elbow_1_B"/>
    <origin rpy="0.0 0.0 0.0" xyz="0.0 0.0 0.3"/>
    <limit effort="300" lower="-3.14" upper="3.14" velocity="5.7"/>
  </joint>
  <link name="L_2_elbow_1_B">
    <visual>
      <origin rpy="0 0 0" xyz="0 0 0.1"/>
      <geometry>
        <cylinder length="0.2" radius="0.06"/>
      </geometry>
      <material name="white"/>
    </visual>
    <visual>
      <origin rpy="1.57 0 0" xyz="0 0.1 0.2"/>
      <geometry>
        <cylinder length="0.2" radius="0.06"/>
      </geometry>
      <material name="white"/>
    </visual>
    <visual>
      <origin rpy="0 0 0" xyz="0 0 0.2"/>
      <geometry>
        <sphere radius="0.06"/>
      </geometry>
      <material name="white"/>
    </visual>
    <collision>
      <origin rpy="0 0 0" xyz="0 0 0.1"/>
      <geometry>
        <cylinder length="0.2" radius="0.06"/>
      </geometry>
    </collision>
    <inertial>
      <origin rpy="0 0 0" xyz="0 0 0.1"/>
      <mass value="0.5"/>
      <inertia ixx="0.0171166666667" ixy="0.0" ixz="0.0" iyy="0.0140083333333" iyz="0.0" izz="0.00400833333333"/>
    </inertial>
    <collision>
      <origin rpy="1.57 0 0" xyz="0 0.1 0.2"/>
      <geometry>
        <cylinder length="0.2" radius="0.06"/>
      </geometry>
    </collision>
    <collision>
      <origin rpy="0 0 0" xyz="0 0 0.2"/>
      <geometry>
        <sphere radius="0.06"/>
      </geometry>
    </collision>
  </link>
  <gazebo reference="L_2_elbow_1_B">
    <mu1>0.2</mu1>
    <mu2>0.2</mu2>
    <kp>1000000.0</kp>
    <kd>1.0</kd>
    <maxVel>0.0</maxVel>
    <minDepth>0.0001</minDepth>
  </gazebo>

  <link name="L_2_link_2_B">
    <visual>
      <origin rpy="0 0 0" xyz="0 0 0.15"/>
      <geometry>
        <cylinder length="0.3" radius="0.06"/>
      </geometry>
      <material name="black"/>
    </visual>
    <collision>
      <origin rpy="0 0 0" xyz="0 0 0.15"/>
      <geometry>
        <cylinder length="0.3" radius="0.06"/>
      </geometry>
    </collision>
    <inertial>
      <origin rpy="0 0 0" xyz="0 0 0.15"/>
      <mass value="0.5"/>
      <inertia ixx="0.0042" ixy="0.0" ixz="0.0" iyy="0.0042" iyz="0.0" izz="0.0009"/>
    </inertial>
  </link>
  <gazebo reference="L_2_link_2_B">
    <mu1>0.2</mu1>
    <mu2>0.2</mu2>
    <kp>1000000.0</kp>
    <kd>1.0</kd>
    <maxVel>0.0</maxVel>
    <minDepth>0.0001</minDepth>
  </gazebo>
  <joint name="L_2_fixed_joint_2_B" type="fixed">
    <axis rpy="0 0 0" xyz="0 0 1"/>
    <parent link="L_2_elbow_1_B"/>
    <child link="L_2_link_2_B"/>
    <origin rpy="-1.57 -0.0 0.0" xyz="0.0 0.199999936586 0.200159265342"/>
  </joint>

  <joint name="J3_B" type="revolute">
    <axis rpy="0 0 0" xyz="0 0 1"/>
    <parent link="L_2_link_2_B"/>
    <child link="L_3_elbow_1_B"/>
    <origin rpy="0.0 0.0 0.0" xyz="0.0 0.0 0.3"/>
    <limit effort="300" lower="-3.14" upper="3.14" velocity="5.7"/>
  </joint>
  <link name="L_3_elbow_1_B">
    <visual>
      <origin rpy="0 0 0" xyz="0 0 0.1"/>
      <geometry>
        <cylinder length="0.2" radius="0.06"/>
      </geometry>
      <material name="white"/>
    </visual>
    <visual>
      <origin rpy="1.57 0 0" xyz="0 0.1 0.2"/>
      <geometry>
        <cylinder length="0.2" radius="0.06"/>
      </geometry>
      <material name="white"/>
    </visual>
    <visual>
      <origin rpy="0 0 0" xyz="0 0 0.2"/>
      <geometry>
        <sphere radius="0.06"/>
      </geometry>
      <material name="white"/>
    </visual>
    <collision>
      <origin rpy="0 0 0" xyz="0 0 0.1"/>
      <geometry>
        <cylinder length="0.2" radius="0.06"/>
      </geometry>
    </collision>
    <inertial>
      <origin rpy="0 0 0" xyz="0 0 0.1"/>
      <mass value="0.5"/>
      <inertia ixx="0.0171166666667" ixy="0.0" ixz="0.0" iyy="0.0140083333333" iyz="0.0" izz="0.00400833333333"/>
    </inertial>
    <collision>
      <origin rpy="1.57 0 0" xyz="0 0.1 0.2"/>
      <geometry>
        <cylinder length="0.2" radius="0.06"/>
      </geometry>
    </collision>
    <collision>
      <origin rpy="0 0 0" xyz="0 0 0.2"/>
      <geometry>
        <sphere radius="0.06"/>
      </geometry>
    </collision>
  </link>
  <gazebo reference="L_3_elbow_1_B">
    <mu1>0.2</mu1>
    <mu2>0.2</mu2>
    <kp>1000000.0</kp>
    <kd>1.0</kd>
    <maxVel>0.0</maxVel>
    <minDepth>0.0001</minDepth>
  </gazebo>

  <link name="L_3_link_2_B">
    <visual>
      <origin rpy="0 0 0" xyz="0 0 0.15"/>
      <geometry>
        <cylinder length="0.3" radius="0.06"/>
      </geometry>
      <material name="black"/>
    </visual>
    <collision>
      <origin rpy="0 0 0" xyz="0 0 0.15"/>
      <geometry>
        <cylinder length="0.3" radius="0.06"/>
      </geometry>
    </collision>
    <inertial>
      <origin rpy="0 0 0" xyz="0 0 0.15"/>
      <mass value="0.5"/>
      <inertia ixx="0.0042" ixy="0.0" ixz="0.0" iyy="0.0042" iyz="0.0" izz="0.0009"/>
    </inertial>
  </link>
  <gazebo reference="L_3_link_2_B">
    <mu1>0.2</mu1>
    <mu2>0.2</mu2>
    <kp>1000000.0</kp>
    <kd>1.0</kd>
    <maxVel>0.0</maxVel>
    <minDepth>0.0001</minDepth>
  </gazebo>
  <joint name="L_3_fixed_joint_2_B" type="fixed">
    <axis rpy="0 0 0" xyz="0 0 1"/>
    <parent link="L_3_elbow_1_B"/>
    <child link="L_3_link_2_B"/>
    <origin rpy="-1.57 -0.0 0.0" xyz="0.0 0.199999936586 0.200159265342"/>
  </joint>

  <joint name="J4_B" type="revolute">
    <axis rpy="0 0 0" xyz="0 0 1"/>
    <parent link="L_3_link_2_B"/>
    <child link="L_4_elbow_1_B"/>
    <origin rpy="0.0 0.0 0.0" xyz="0.0 0.0 0.3"/>
    <limit effort="300" lower="-3.14" upper="3.14" velocity="5.7"/>
  </joint>
  <link name="L_4_elbow_1_B">
    <visual>
      <origin rpy="0 0 0" xyz="0 0 0.1"/>
      <geometry>
        <cylinder length="0.2" radius="0.06"/>
      </geometry>
      <material name="white"/>
    </visual>
    <visual>
      <origin rpy="1.57 0 0" xyz="0 0.1 0.2"/>
      <geometry>
        <cylinder length="0.2" radius="0.06"/>
      </geometry>
      <material name="white"/>
    </visual>
    <visual>
      <origin rpy="0 0 0" xyz="0 0 0.2"/>
      <geometry>
        <sphere radius="0.06"/>
      </geometry>
      <material name="white"/>
    </visual>
    <collision>
      <origin rpy="0 0 0" xyz="0 0 0.1"/>
      <geometry>
        <cylinder length="0.2" radius="0.06"/>
      </geometry>
    </collision>
    <inertial>
      <origin rpy="0 0 0" xyz="0 0 0.1"/>
      <mass value="0.5"/>
      <inertia ixx="0.0171166666667" ixy="0.0" ixz="0.0" iyy="0.0140083333333" iyz="0.0" izz="0.00400833333333"/>
    </inertial>
    <collision>
      <origin rpy="1.57 0 0" xyz="0 0.1 0.2"/>
      <geometry>
        <cylinder length="0.2" radius="0.06"/>
      </geometry>
    </collision>
    <collision>
      <origin rpy="0 0 0" xyz="0 0 0.2"/>
      <geometry>
        <sphere radius="0.06"/>
      </geometry>
    </collision>
  </link>
  <gazebo reference="L_4_elbow_1_B">
    <mu1>0.2</mu1>
    <mu2>0.2</mu2>
    <kp>1000000.0</kp>
    <kd>1.0</kd>
    <maxVel>0.0</maxVel>
    <minDepth>0.0001</minDepth>
  </gazebo>

    <link name="L_4_link_2_B">
    <visual>
      <origin rpy="0 0 0" xyz="0 0 0.15"/>
      <geometry>
        <cylinder length="0.3" radius="0.06"/>
      </geometry>
      <material name="black"/>
    </visual>
    <collision>
      <origin rpy="0 0 0" xyz="0 0 0.15"/>
      <geometry>
        <cylinder length="0.3" radius="0.06"/>
      </geometry>
    </collision>
    <inertial>
      <origin rpy="0 0 0" xyz="0 0 0.15"/>
      <mass value="0.5"/>
      <inertia ixx="0.0042" ixy="0.0" ixz="0.0" iyy="0.0042" iyz="0.0" izz="0.0009"/>
    </inertial>
  </link>
  <gazebo reference="L_4_link_2_B">
    <mu1>0.2</mu1>
    <mu2>0.2</mu2>
    <kp>1000000.0</kp>
    <kd>1.0</kd>
    <maxVel>0.0</maxVel>
    <minDepth>0.0001</minDepth>
  </gazebo>
  <joint name="L_4_fixed_joint_2_B" type="fixed">
    <axis rpy="0 0 0" xyz="0 0 1"/>
    <parent link="L_4_elbow_1_B"/>
    <child link="L_4_link_2_B"/>
    <origin rpy="-1.57 -0.0 0.0" xyz="0.0 0.199999936586 0.200159265342"/>
  </joint>

  <joint name="J5_B" type="revolute">
    <axis rpy="0 0 0" xyz="0 0 1"/>
    <parent link="L_4_link_2_B"/>
    <child link="L_5_elbow_1_B"/>
    <origin rpy="0.0 0.0 0.0" xyz="0.0 0.0 0.3"/>
    <limit effort="300" lower="-3.14" upper="3.14" velocity="5.7"/>
  </joint>
  <link name="L_5_elbow_1_B">
    <visual>
      <origin rpy="0 0 0" xyz="0 0 0.1"/>
      <geometry>
        <cylinder length="0.2" radius="0.06"/>
      </geometry>
      <material name="white"/>
    </visual>
    <visual>
      <origin rpy="1.57 0 0" xyz="0 0.1 0.2"/>
      <geometry>
        <cylinder length="0.2" radius="0.06"/>
      </geometry>
      <material name="white"/>
    </visual>
    <visual>
      <origin rpy="0 0 0" xyz="0 0 0.2"/>
      <geometry>
        <sphere radius="0.06"/>
      </geometry>
      <material name="white"/>
    </visual>
    <collision>
      <origin rpy="0 0 0" xyz="0 0 0.1"/>
      <geometry>
        <cylinder length="0.2" radius="0.06"/>
      </geometry>
    </collision>
    <inertial>
      <origin rpy="0 0 0" xyz="0 0 0.1"/>
      <mass value="0.5"/>
      <inertia ixx="0.0171166666667" ixy="0.0" ixz="0.0" iyy="0.0140083333333" iyz="0.0" izz="0.00400833333333"/>
    </inertial>
    <collision>
      <origin rpy="1.57 0 0" xyz="0 0.1 0.2"/>
      <geometry>
        <cylinder length="0.2" radius="0.06"/>
      </geometry>
    </collision>
    <collision>
      <origin rpy="0 0 0" xyz="0 0 0.2"/>
      <geometry>
        <sphere radius="0.06"/>
      </geometry>
    </collision>
  </link>
  <gazebo reference="L_5_elbow_1_B">
    <mu1>0.2</mu1>
    <mu2>0.2</mu2>
    <kp>1000000.0</kp>
    <kd>1.0</kd>
    <maxVel>0.0</maxVel>
    <minDepth>0.0001</minDepth>
  </gazebo>

  <joint name="J6_B" type="revolute">
    <axis rpy="0 0 0" xyz="0 0 1"/>
    <parent link="L_5_elbow_1_B"/>
    <child link="L_6_elbow_1_B"/>
    <origin rpy="-1.57 -0.0 0.0" xyz="0.0 0.199999936586 0.200159265342"/>
    <limit effort="300" lower="-3.14" upper="3.14" velocity="5.7"/>
  </joint>
  <link name="L_6_elbow_1_B">
    <visual>
      <origin rpy="0 0 0" xyz="0 0 0.1"/>
      <geometry>
        <cylinder length="0.2" radius="0.06"/>
      </geometry>
      <material name="white"/>
    </visual>
    <visual>
      <origin rpy="1.57 0 0" xyz="0 0.1 0.2"/>
      <geometry>
        <cylinder length="0.2" radius="0.06"/>
      </geometry>
      <material name="white"/>
    </visual>
    <visual>
      <origin rpy="0 0 0" xyz="0 0 0.2"/>
      <geometry>
        <sphere radius="0.06"/>
      </geometry>
      <material name="white"/>
    </visual>
    <collision>
      <origin rpy="0 0 0" xyz="0 0 0.1"/>
      <geometry>
        <cylinder length="0.2" radius="0.06"/>
      </geometry>
    </collision>
    <inertial>
      <origin rpy="0 0 0" xyz="0 0 0.1"/>
      <mass value="0.5"/>
      <inertia ixx="0.0171166666667" ixy="0.0" ixz="0.0" iyy="0.0140083333333" iyz="0.0" izz="0.00400833333333"/>
    </inertial>
    <collision>
      <origin rpy="1.57 0 0" xyz="0 0.1 0.2"/>
      <geometry>
        <cylinder length="0.2" radius="0.06"/>
      </geometry>
    </collision>
    <collision>
      <origin rpy="0 0 0" xyz="0 0 0.2"/>
      <geometry>
        <sphere radius="0.06"/>
      </geometry>
    </collision>
  </link>
  <gazebo reference="L_6_elbow_1_B">
    <mu1>0.2</mu1>
    <mu2>0.2</mu2>
    <kp>1000000.0</kp>
    <kd>1.0</kd>
    <maxVel>0.0</maxVel>
    <minDepth>0.0001</minDepth>
  </gazebo>

  <link name="L_6_link_2_B">
    <visual>
      <origin rpy="0 0 0" xyz="0 0 0.15"/>
      <geometry>
        <cylinder length="0.3" radius="0.06"/>
      </geometry>
      <material name="black"/>
    </visual>
    <collision>
      <origin rpy="0 0 0" xyz="0 0 0.15"/>
      <geometry>
        <cylinder length="0.3" radius="0.06"/>
      </geometry>
    </collision>
    <inertial>
      <origin rpy="0 0 0" xyz="0 0 0.15"/>
      <mass value="0.5"/>
      <inertia ixx="0.0042" ixy="0.0" ixz="0.0" iyy="0.0042" iyz="0.0" izz="0.0009"/>
    </inertial>
  </link>
  <gazebo reference="L_6_link_2_B">
    <mu1>0.2</mu1>
    <mu2>0.2</mu2>
    <kp>1000000.0</kp>
    <kd>1.0</kd>
    <maxVel>0.0</maxVel>
    <minDepth>0.0001</minDepth>
  </gazebo>
  <joint name="L_6_fixed_joint_2_B" type="fixed">
    <axis rpy="0 0 0" xyz="0 0 1"/>
    <parent link="L_6_elbow_1_B"/>
    <child link="L_6_link_2_B"/>
    <origin rpy="-1.57 -0.0 0.0" xyz="0.0 0.199999936586 0.200159265342"/>
  </joint>

  <!-- Gazebo plugin for external force -->
  <gazebo>
    <plugin name="gazebo_force_plugin" filename="libgazebo_force_plugin.so">
      <!-- <robotNamespace>/</robotNamespace> -->
    </plugin>
  </gazebo>
  
</robot>
