<sdf version='1.6'>
  <model name='ModularBot'>
    <link name='base_link'>
      <pose frame=''>0 0 0 0 -0 0</pose>
      <inertial>
        <pose frame=''>0 0 0.06647 0 -0 0</pose>
        <mass>4.05549</mass>
        <inertia>
          <ixx>0.0291229</ixx>
          <ixy>-1.14168e-05</ixy>
          <ixz>2.71689e-06</ixz>
          <iyy>0.0290192</iyy>
          <iyz>8.76312e-05</iyz>
          <izz>0.00420263</izz>
        </inertia>
      </inertial>
      <collision name='base_link_fixed_joint_lump__J1_A_stator_collision'>
        <pose frame=''>0 0 0 0 -0 0</pose>
        <geometry>
          <mesh>
            <scale>0.001 0.001 0.001</scale>
            <uri>model://modular/meshes/simple/yaw_base.stl</uri>
          </mesh>
        </geometry>
        <surface>
          <contact>
            <ode>
              <kp>1e+06</kp>
              <kd>1</kd>
              <max_vel>0</max_vel>
              <min_depth>0.0001</min_depth>
            </ode>
          </contact>
          <friction>
            <ode>
              <mu>0.2</mu>
              <mu2>0.2</mu2>
            </ode>
          </friction>
        </surface>
      </collision>
      <visual name='base_link_fixed_joint_lump__J1_A_stator_visual'>
        <pose frame=''>0 0 0 0 -0 0</pose>
        <geometry>
          <mesh>
            <scale>0.001 0.001 0.001</scale>
            <uri>model://modular/meshes/yaw_base.stl</uri>
          </mesh>
        </geometry>
        <material>
          <script>
            <name>Gazebo/Blue</name>
            <uri>file://media/materials/scripts/gazebo.material</uri>
          </script>
        </material>
      </visual>
      <gravity>1</gravity>
      <velocity_decay/>
    </link>
    <joint name='world_fixed' type='fixed'>
      <child>base_link</child>
      <parent>world</parent>
    </joint>
    <link name='L_1_A'>
      <pose frame=''>0 0 0.214 0 -0 0</pose>
      <inertial>
        <pose frame=''>-0.00061 -0.010408 0.066157 0 -0 0</pose>
        <mass>2.48315</mass>
        <inertia>
          <ixx>0.0213023</ixx>
          <ixy>8.93223e-06</ixy>
          <ixz>0.000522965</ixz>
          <iyy>0.0201354</iyy>
          <iyz>0.00107135</iyz>
          <izz>0.133639</izz>
        </inertia>
      </inertial>
      <collision name='L_1_A_collision'>
        <pose frame=''>0 0 0 0 -0 0</pose>
        <geometry>
          <mesh>
            <scale>0.001 0.001 0.001</scale>
            <uri>model://modular/meshes/simple/yaw_link.stl</uri>
          </mesh>
        </geometry>
      </collision>
      <collision name='L_1_A_fixed_joint_lump__J2_A_stator_collision_1'>
        <pose frame=''>0 0 0 0 -0 0</pose>
        <geometry>
          <mesh>
            <scale>0.001 0.001 0.001</scale>
            <uri>model://modular/meshes/simple/elbow_base.stl</uri>
          </mesh>
        </geometry>
        <surface>
          <contact>
            <ode>
              <kp>1e+06</kp>
              <kd>1</kd>
              <max_vel>0</max_vel>
              <min_depth>0.0001</min_depth>
            </ode>
          </contact>
          <friction>
            <ode>
              <mu>0.2</mu>
              <mu2>0.2</mu2>
            </ode>
          </friction>
        </surface>
      </collision>
      <visual name='L_1_A_visual'>
        <pose frame=''>0 0 0 0 -0 0</pose>
        <geometry>
          <mesh>
            <scale>0.001 0.001 0.001</scale>
            <uri>model://modular/meshes/yaw_link.stl</uri>
          </mesh>
        </geometry>
      </visual>
      <visual name='L_1_A_fixed_joint_lump__J2_A_stator_visual_1'>
        <pose frame=''>0 0 0 0 -0 0</pose>
        <geometry>
          <mesh>
            <scale>0.001 0.001 0.001</scale>
            <uri>model://modular/meshes/elbow_base.stl</uri>
          </mesh>
        </geometry>
        <material>
          <script>
            <name>Gazebo/Blue</name>
            <uri>file://media/materials/scripts/gazebo.material</uri>
          </script>
        </material>
      </visual>
      <gravity>1</gravity>
      <velocity_decay/>
    </link>
    <joint name='J1_A' type='revolute'>
      <child>L_1_A</child>
      <parent>base_link</parent>
      <axis>
        <xyz>0 0 1</xyz>
        <limit>
          <lower>-3.14</lower>
          <upper>3.14</upper>
          <effort>55</effort>
          <velocity>11.7</velocity>
        </limit>
        <dynamics>
          <spring_reference>0</spring_reference>
          <spring_stiffness>0</spring_stiffness>
        </dynamics>
        <use_parent_model_frame>1</use_parent_model_frame>
      </axis>
    </joint>
    <link name='L_2_A'>
      <pose frame=''>0 0.07215 0.346057 -1.57 0 0</pose>
      <inertial>
        <pose frame=''>-0.000667 -0.161269 -0.072064 0 -0 0</pose>
        <mass>3.16357</mass>
        <inertia>
          <ixx>0.0425677</ixx>
          <ixy>-0.00014774</ixy>
          <ixz>0.000377927</ixz>
          <iyy>0.00865763</iyy>
          <iyz>-0.00539631</iyz>
          <izz>0.167932</izz>
        </inertia>
      </inertial>
      <collision name='L_2_A_collision'>
        <pose frame=''>0 0 -0.072 3.14159 0.001593 3.14159</pose>
        <geometry>
          <mesh>
            <scale>0.001 0.001 0.001</scale>
            <uri>model://modular/meshes/simple/elbow_link.stl</uri>
          </mesh>
        </geometry>
      </collision>
      <collision name='L_2_A_fixed_joint_lump__J3_A_stator_collision_1'>
        <pose frame=''>0 -0.132 -0.072045 1.57 -0 0</pose>
        <geometry>
          <mesh>
            <scale>0.001 0.001 0.001</scale>
            <uri>model://modular/meshes/simple/elbow_base.stl</uri>
          </mesh>
        </geometry>
        <surface>
          <contact>
            <ode>
              <kp>1e+06</kp>
              <kd>1</kd>
              <max_vel>0</max_vel>
              <min_depth>0.0001</min_depth>
            </ode>
          </contact>
          <friction>
            <ode>
              <mu>0.2</mu>
              <mu2>0.2</mu2>
            </ode>
          </friction>
        </surface>
      </collision>
      <visual name='L_2_A_visual'>
        <pose frame=''>0 0 -0.072 3.14159 0.001593 3.14159</pose>
        <geometry>
          <mesh>
            <scale>0.001 0.001 0.001</scale>
            <uri>model://modular/meshes/elbow_link.stl</uri>
          </mesh>
        </geometry>
      </visual>
      <visual name='L_2_A_fixed_joint_lump__J3_A_stator_visual_1'>
        <pose frame=''>0 -0.132 -0.072045 1.57 -0 0</pose>
        <geometry>
          <mesh>
            <scale>0.001 0.001 0.001</scale>
            <uri>model://modular/meshes/elbow_base.stl</uri>
          </mesh>
        </geometry>
        <material>
          <script>
            <name>Gazebo/Blue</name>
            <uri>file://media/materials/scripts/gazebo.material</uri>
          </script>
        </material>
      </visual>
      <gravity>1</gravity>
      <velocity_decay/>
    </link>
    <joint name='J2_A' type='revolute'>
      <child>L_2_A</child>
      <parent>L_1_A</parent>
      <axis>
        <xyz>0 1 0.000796</xyz>
        <limit>
          <lower>-3.14</lower>
          <upper>3.14</upper>
          <effort>55</effort>
          <velocity>11.7</velocity>
        </limit>
        <dynamics>
          <spring_reference>0</spring_reference>
          <spring_stiffness>0</spring_stiffness>
        </dynamics>
        <use_parent_model_frame>1</use_parent_model_frame>
      </axis>
    </joint>
    <link name='L_3_A'>
      <pose frame=''>0 0.07215 0.610057 -1.57 0 0</pose>
      <inertial>
        <pose frame=''>-7.1e-05 -0.181121 -0.064461 0 -0 0</pose>
        <mass>3.35626</mass>
        <inertia>
          <ixx>0.0537199</ixx>
          <ixy>2.2727e-05</ixy>
          <ixz>0.000383208</ixz>
          <iyy>0.00753791</iyy>
          <iyz>-0.00369324</iyz>
          <izz>0.18061</izz>
        </inertia>
      </inertial>
      <collision name='L_3_A_collision'>
        <pose frame=''>0 0 -0.072 3.14159 0.001593 3.14159</pose>
        <geometry>
          <mesh>
            <scale>0.001 0.001 0.001</scale>
            <uri>model://modular/meshes/simple/elbow_link.stl</uri>
          </mesh>
        </geometry>
      </collision>
      <collision name='L_3_A_fixed_joint_lump__J4_A_stator_collision_1'>
        <pose frame=''>0 -0.132 -0.072045 1.57 -0 0</pose>
        <geometry>
          <mesh>
            <scale>0.001 0.001 0.001</scale>
            <uri>model://modular/meshes/simple/yaw_base.stl</uri>
          </mesh>
        </geometry>
        <surface>
          <contact>
            <ode>
              <kp>1e+06</kp>
              <kd>1</kd>
              <max_vel>0</max_vel>
              <min_depth>0.0001</min_depth>
            </ode>
          </contact>
          <friction>
            <ode>
              <mu>0.2</mu>
              <mu2>0.2</mu2>
            </ode>
          </friction>
        </surface>
      </collision>
      <visual name='L_3_A_visual'>
        <pose frame=''>0 0 -0.072 3.14159 0.001593 3.14159</pose>
        <geometry>
          <mesh>
            <scale>0.001 0.001 0.001</scale>
            <uri>model://modular/meshes/elbow_link.stl</uri>
          </mesh>
        </geometry>
      </visual>
      <visual name='L_3_A_fixed_joint_lump__J4_A_stator_visual_1'>
        <pose frame=''>0 -0.132 -0.072045 1.57 -0 0</pose>
        <geometry>
          <mesh>
            <scale>0.001 0.001 0.001</scale>
            <uri>model://modular/meshes/yaw_base.stl</uri>
          </mesh>
        </geometry>
        <material>
          <script>
            <name>Gazebo/Blue</name>
            <uri>file://media/materials/scripts/gazebo.material</uri>
          </script>
        </material>
      </visual>
      <gravity>1</gravity>
      <velocity_decay/>
    </link>
    <joint name='J3_A' type='revolute'>
      <child>L_3_A</child>
      <parent>L_2_A</parent>
      <axis>
        <xyz>0 1 0.000796</xyz>
        <limit>
          <lower>-3.14</lower>
          <upper>3.14</upper>
          <effort>55</effort>
          <velocity>11.7</velocity>
        </limit>
        <dynamics>
          <spring_reference>0</spring_reference>
          <spring_stiffness>0</spring_stiffness>
        </dynamics>
        <use_parent_model_frame>1</use_parent_model_frame>
      </axis>
    </joint>
    <link name='L_4_A'>
      <pose frame=''>0 -0 0.956 0 -0 0</pose>
      <inertial>
        <pose frame=''>-0.00061 -0.010408 0.066157 0 -0 0</pose>
        <mass>2.48315</mass>
        <inertia>
          <ixx>0.0213023</ixx>
          <ixy>8.93223e-06</ixy>
          <ixz>0.000522965</ixz>
          <iyy>0.0201354</iyy>
          <iyz>0.00107135</iyz>
          <izz>0.133639</izz>
        </inertia>
      </inertial>
      <collision name='L_4_A_collision'>
        <pose frame=''>0 0 0 0 -0 0</pose>
        <geometry>
          <mesh>
            <scale>0.001 0.001 0.001</scale>
            <uri>model://modular/meshes/simple/yaw_link.stl</uri>
          </mesh>
        </geometry>
      </collision>
      <collision name='L_4_A_fixed_joint_lump__J5_A_stator_collision_1'>
        <pose frame=''>0 0 0 0 -0 0</pose>
        <geometry>
          <mesh>
            <scale>0.001 0.001 0.001</scale>
            <uri>model://modular/meshes/simple/elbow_base.stl</uri>
          </mesh>
        </geometry>
        <surface>
          <contact>
            <ode>
              <kp>1e+06</kp>
              <kd>1</kd>
              <max_vel>0</max_vel>
              <min_depth>0.0001</min_depth>
            </ode>
          </contact>
          <friction>
            <ode>
              <mu>0.2</mu>
              <mu2>0.2</mu2>
            </ode>
          </friction>
        </surface>
      </collision>
      <visual name='L_4_A_visual'>
        <pose frame=''>0 0 0 0 -0 0</pose>
        <geometry>
          <mesh>
            <scale>0.001 0.001 0.001</scale>
            <uri>model://modular/meshes/yaw_link.stl</uri>
          </mesh>
        </geometry>
      </visual>
      <visual name='L_4_A_fixed_joint_lump__J5_A_stator_visual_1'>
        <pose frame=''>0 0 0 0 -0 0</pose>
        <geometry>
          <mesh>
            <scale>0.001 0.001 0.001</scale>
            <uri>model://modular/meshes/elbow_base.stl</uri>
          </mesh>
        </geometry>
        <material>
          <script>
            <name>Gazebo/Blue</name>
            <uri>file://media/materials/scripts/gazebo.material</uri>
          </script>
        </material>
      </visual>
      <gravity>1</gravity>
      <velocity_decay/>
    </link>
    <joint name='J4_A' type='revolute'>
      <child>L_4_A</child>
      <parent>L_3_A</parent>
      <axis>
        <xyz>0 0 1</xyz>
        <limit>
          <lower>-3.14</lower>
          <upper>3.14</upper>
          <effort>55</effort>
          <velocity>11.7</velocity>
        </limit>
        <dynamics>
          <spring_reference>0</spring_reference>
          <spring_stiffness>0</spring_stiffness>
        </dynamics>
        <use_parent_model_frame>1</use_parent_model_frame>
      </axis>
    </joint>
    <link name='L_5_A'>
      <pose frame=''>0 0.07215 1.08806 -1.57 0 0</pose>
      <inertial>
        <pose frame=''>0.00282 -0.103955 -0.060736 0 -0 0</pose>
        <mass>2.23477</mass>
        <inertia>
          <ixx>0.0169745</ixx>
          <ixy>0.000484741</ixy>
          <ixz>0.000467442</ixz>
          <iyy>0.00484454</iyy>
          <iyz>-0.00167853</iyz>
          <izz>0.14418</izz>
        </inertia>
      </inertial>
      <collision name='L_5_A_collision'>
        <pose frame=''>0 0 -0.072 3.14159 0.001593 3.14159</pose>
        <geometry>
          <mesh>
            <scale>0.001 0.001 0.001</scale>
            <uri>model://modular/meshes/simple/elbow_link.stl</uri>
          </mesh>
        </geometry>
      </collision>
      <collision name='L_5_A_fixed_joint_lump__tool_exchanger_A_collision_1'>
        <pose frame=''>0 -0.132 -0.072045 1.57 -0 0</pose>
        <geometry>
          <mesh>
            <scale>0.001 0.001 0.001</scale>
            <uri>model://modular/meshes/tool_exchanger.stl</uri>
          </mesh>
        </geometry>
      </collision>
      <visual name='L_5_A_visual'>
        <pose frame=''>0 0 -0.072 3.14159 0.001593 3.14159</pose>
        <geometry>
          <mesh>
            <scale>0.001 0.001 0.001</scale>
            <uri>model://modular/meshes/elbow_link.stl</uri>
          </mesh>
        </geometry>
      </visual>
      <visual name='L_5_A_fixed_joint_lump__tool_exchanger_A_visual_1'>
        <pose frame=''>0 -0.132 -0.072045 1.57 -0 0</pose>
        <geometry>
          <mesh>
            <scale>0.001 0.001 0.001</scale>
            <uri>model://modular/meshes/tool_exchanger.stl</uri>
          </mesh>
        </geometry>
      </visual>
    </link>
    <joint name='J5_A' type='revolute'>
      <child>L_5_A</child>
      <parent>L_4_A</parent>
      <axis>
        <xyz>0 1 0.000796</xyz>
        <limit>
          <lower>-3.14</lower>
          <upper>3.14</upper>
          <effort>55</effort>
          <velocity>11.7</velocity>
        </limit>
        <dynamics>
          <spring_reference>0</spring_reference>
          <spring_stiffness>0</spring_stiffness>
        </dynamics>
        <use_parent_model_frame>1</use_parent_model_frame>
      </axis>
    </joint>
    <static>0</static>
    <plugin name='gazebo_xbot_plugin' filename='libGazeboXBotPlugin.so'/>
  </model>
</sdf>
