<?xml version="1.0"?>
<robot name="ModularBot" xmlns:xacro="http://www.ros.org/wiki/xacro">
    <xacro:arg name="modular_path" default="missing_argument_modular_path"/>
    <xacro:property name="MODULAR_PATH" value="$(arg modular_path)" />

    <xacro:include filename="${MODULAR_PATH}/modular_data/urdf/ModularBot.library.urdf.xacro"/>
    <xacro:include filename="${MODULAR_PATH}/modular_data/urdf/ModularBot.control.urdf.xacro"/>

    <xacro:arg name="floating_base" default="false"/>
    <xacro:property name="ADD_FLOATING_BASE" value="$(arg floating_base)" />

    <xacro:arg name="gazebo_urdf" default="false"/>
    <xacro:property name="GAZEBO_URDF" value="$(arg gazebo_urdf)" />

    <xacro:arg name="realsense" default="false"/>
    <xacro:property name="ADD_CAMERAS" value="$(arg realsense)" />

    <xacro:arg name="velodyne" default="false"/>
    <xacro:property name="ADD_VELODYNE" value="$(arg velodyne)" />

    <xacro:arg name="ultrasound" default="false"/>
    <xacro:property name="ADD_ULTRASOUND" value="$(arg ultrasound)" />

    <xacro:arg name="use_gpu_ray" default="false"/>
    <xacro:property name="USE_GPU_RAY" value="$(arg use_gpu_ray)" />

    <!-- adding (or not) world link for Gazebo simulation -->
    <xacro:if value="${ADD_FLOATING_BASE}">

        <xacro:unless value="${GAZEBO_URDF}">
            <link name="world"/>
            <joint name="reference" type="floating">
                <parent link="world"/>
                <child link="base_link"/>
            </joint>
        </xacro:unless>

        <origin xyz="0.0 0.0 0.8" rpy="0 0 0" />

    </xacro:if>
    <xacro:unless value="${ADD_FLOATING_BASE}">

        <link name="world"/>
        <joint name="reference" type="fixed">
            <parent link="world"/>
            <child link="base_link"/>
        </joint>

    </xacro:unless>

    <link name="base_link">
        <xacro:default_inertial mass="0.001"/>
    </link>

</robot>
